<!DOCTYPE html><html lang="zh-CN"><head>
  <meta charset="utf-8">
  <meta name="viewport" content="width=device-width">
  <title>错误优先的回调 | Node.js API 文档</title>
  
  

    <link href="../../api/static/inject.css" rel="stylesheet"><link rel="icon" sizes="32x32" type="image/png" href="../../api/static/favicon.png"></head>

<body class="alt apidoc" id="page_api_item">
  <div id="api-section-errors">
    <div id="content" class="clearfix">

      <div id="column1" data-id="__ID__" class="interior">
        <header>
          <h1>错误优先的回调</h1>
          <div id="gtoc">
            <ul>
              <li>v16.16.0</li>
              <li>
                <a href="../errors.html#errors_error_first_callbacks" name="toc">返回上层文档</a>
              </li>

              <li class="picker-header">
    <a href="#">
        <span class="collapsed-arrow">►</span><span class="expanded-arrow">▼</span>
        其他版本
      </a>
    <div class="picker"><ol id="alt-docs">
    <li><a href="../../api/errors/error_first_callbacks.html">18.6.0</a></li><li><a href="">16.16.0</a></li><li><a href="../../api-v14/errors/error_first_callbacks.html">14.20.0</a></li>
</ol></div>
  </li>

              <li>
                <a href="http://api.nodejs.cn/" class="link-to-search">搜索</a>
              </li>
              <li>
                
                
              </li>

              <!-- <li>
                <a href="https://github.com/nodejscn/node-api-cn/edit/master/errors/#error-first-callbacks.md" rel="nofollow">提交修改</a>
              </li> -->
              <!-- <li>
                <a href="/gzh/">公众号</a>
              </li> -->
              <!-- <li class="biz_wrap" data-biz="api_item_nav">
                <a target="_blank" class="biz_title biz_link"></a>
              </li> -->
            </ul>
          </div>
          <hr>
        </header>

        <div id="apicontent">
          <div id="content_left"><p>Node.js 核心 API 暴露的大多数异步方法都遵循称为错误优先回调的惯用模式。
使用这种模式，回调函数作为参数传给方法。
当操作完成或出现错误时，回调函数将使用 <code>Error</code> 对象（如果有）作为第一个参数传入。
如果没有出现错误，则第一个参数将作为 <code>null</code> 传入。</p><pre class=""><code class="language-js"><span class="hljs-keyword">const</span> fs = <span class="hljs-built_in">require</span>(<span class="hljs-string">'fs'</span>);

<span class="hljs-keyword">function</span> <span class="hljs-title function_">errorFirstCallback</span>(<span class="hljs-params">err, data</span>) {
  <span class="hljs-keyword">if</span> (err) {
    <span class="hljs-variable language_">console</span>.<span class="hljs-title function_">error</span>(<span class="hljs-string">'There was an error'</span>, err);
    <span class="hljs-keyword">return</span>;
  }
  <span class="hljs-variable language_">console</span>.<span class="hljs-title function_">log</span>(data);
}

fs.<span class="hljs-title function_">readFile</span>(<span class="hljs-string">'/some/file/that/does-not-exist'</span>, errorFirstCallback);
fs.<span class="hljs-title function_">readFile</span>(<span class="hljs-string">'/some/file/that/does-exist'</span>, errorFirstCallback);</code></pre><p class="">JavaScript <code>try…catch</code> 机制不能用于拦截异步 API 产生的错误。
初学者的一个常见错误是尝试在错误优先的回调中使用 <code>throw</code>：</p><pre class=""><code class="language-js"><span class="hljs-comment">// 这行不通：</span>
<span class="hljs-keyword">const</span> fs = <span class="hljs-built_in">require</span>(<span class="hljs-string">'fs'</span>);

<span class="hljs-keyword">try</span> {
  fs.<span class="hljs-title function_">readFile</span>(<span class="hljs-string">'/some/file/that/does-not-exist'</span>, <span class="hljs-function">(<span class="hljs-params">err, data</span>) =&gt;</span> {
    <span class="hljs-comment">// 错误的假设：在这里抛出...</span>
    <span class="hljs-keyword">if</span> (err) {
      <span class="hljs-keyword">throw</span> err;
    }
  });
} <span class="hljs-keyword">catch</span> (err) {
  <span class="hljs-comment">// 这不会捕获抛出的错误！</span>
  <span class="hljs-variable language_">console</span>.<span class="hljs-title function_">error</span>(err);
}</code></pre><p class="">这不起作用，因为传给 <code>fs.readFile()</code> 的回调函数是异步调用的。
当回调被调用时，周围的代码（包括 <code>try…catch</code> 块）已经退出。
大多数情况下，在回调中抛出错误会使 Node.js 进程崩溃。
如果启用了<a href="../domain.html">域</a>，或者已经在 <code>process.on('uncaughtException')</code> 注册了句柄，则可以拦截此类错误。</p></div>
          <div id="content_right"><p>Most asynchronous methods exposed by the Node.js core API follow an idiomatic
pattern referred to as an <em>error-first callback</em>. With this pattern, a callback
function is passed to the method as an argument. When the operation either
completes or an error is raised, the callback function is called with the
<code>Error</code> object (if any) passed as the first argument. If no error was raised,
the first argument will be passed as <code>null</code>.</p><pre><code class="language-js"><span class="hljs-keyword">const</span> fs = <span class="hljs-built_in">require</span>(<span class="hljs-string">'fs'</span>);

<span class="hljs-keyword">function</span> <span class="hljs-title function_">errorFirstCallback</span>(<span class="hljs-params">err, data</span>) {
  <span class="hljs-keyword">if</span> (err) {
    <span class="hljs-variable language_">console</span>.<span class="hljs-title function_">error</span>(<span class="hljs-string">'There was an error'</span>, err);
    <span class="hljs-keyword">return</span>;
  }
  <span class="hljs-variable language_">console</span>.<span class="hljs-title function_">log</span>(data);
}

fs.<span class="hljs-title function_">readFile</span>(<span class="hljs-string">'/some/file/that/does-not-exist'</span>, errorFirstCallback);
fs.<span class="hljs-title function_">readFile</span>(<span class="hljs-string">'/some/file/that/does-exist'</span>, errorFirstCallback);</code></pre><p>The JavaScript <code>try…catch</code> mechanism <strong>cannot</strong> be used to intercept errors
generated by asynchronous APIs. A common mistake for beginners is to try to
use <code>throw</code> inside an error-first callback:</p><pre><code class="language-js"><span class="hljs-comment">// THIS WILL NOT WORK:</span>
<span class="hljs-keyword">const</span> fs = <span class="hljs-built_in">require</span>(<span class="hljs-string">'fs'</span>);

<span class="hljs-keyword">try</span> {
  fs.<span class="hljs-title function_">readFile</span>(<span class="hljs-string">'/some/file/that/does-not-exist'</span>, <span class="hljs-function">(<span class="hljs-params">err, data</span>) =&gt;</span> {
    <span class="hljs-comment">// Mistaken assumption: throwing here...</span>
    <span class="hljs-keyword">if</span> (err) {
      <span class="hljs-keyword">throw</span> err;
    }
  });
} <span class="hljs-keyword">catch</span> (err) {
  <span class="hljs-comment">// This will not catch the throw!</span>
  <span class="hljs-variable language_">console</span>.<span class="hljs-title function_">error</span>(err);
}</code></pre><p>This will not work because the callback function passed to <code>fs.readFile()</code> is
called asynchronously. By the time the callback has been called, the
surrounding code, including the <code>try…catch</code> block, will have already exited.
Throwing an error inside the callback <strong>can crash the Node.js process</strong> in most
cases. If <a href="../domain.html">domains</a> are enabled, or a handler has been registered with
<code>process.on('uncaughtException')</code>, such errors can be intercepted.</p></div>
          <div></div>
        </div>

        <!-- <div id="biz_item" class="biz_wrap" data-biz="api_item">
          <a target="_blank" class="biz_link">
            <img class="biz_img" />
          </a>
        </div> -->
      </div>
    </div>
  </div>
  
  <div id="wxpaycode_box" style="display: none;">
    <div id="wxpaycode_img_box">
      <div id="wxpaycode_vip_tips">
        因经营维护成本巨大，
        <br>为了能提供更高质量的中文文档，
        <br>即日起将只对VIP会员开放。
        <br>扫码成为VIP会员，会员费用为<span id="wxpaycode_vip_money">199</span>元/年
      </div>
      <img id="wxpaycode_img">
    </div>
  </div>
  
  
  



    <script src="../../api/static/inject.js" defer=""></script></body></html>